<?xml version="1.0" ?>
<robot xmlns:xacro="http://www.ros.org/wiki/xacro">

<xacro:include filename="$(find omni_3wd)/urdf/roller.urdf.xacro"/>

<xacro:macro
	name="rim_macro"
	params="name color xyz rpy">

		<link name="rim_${name}_link">
			<gravity>true</gravity>
			<inertial>
				<origin xyz="0 0 -0.001029"/>
				<mass value="0.22565466"/>
				<inertia
					ixx="0.00016127521"
					ixy="0"
					ixz="0"
					iyy="0.00016127521"
					iyz="0"
					izz="0.00022850091"/>

			</inertial>
			<visual>
				<geometry>

					<mesh filename="package://omni_3wd/mesh/rim.stl" scale="3.0 3.0 3.0"/>
				</geometry>
				<material name="rim_${name}_material">
					<color rgba="${color} 1"/>
				</material>
			</visual>
			<collision>
				<geometry>
					<mesh filename="package://omni_3wd/mesh/rim.stl" scale="3.0 3.0 3.0"/>
				</geometry>
			</collision>
			
		</link>

		<joint
			name="rim_${name}_joint"
			type="continuous">

			<parent link="base_link" />
			<child link="rim_${name}_link" />
			<axis xyz="0 0 1"/>
			<origin xyz="${xyz}" rpy="${rpy}"/>

		</joint>
		<xacro:roller_macro
			parent="${name}"
			name="e"
			xyz="0.04065 0 0.0165"
			rpy="-1.570796326794896 0 0"
		/>
		<xacro:roller_macro
			parent="${name}"
			name="ne"
			xyz="0.02874389067 0.02874389067 -0.0165"
			rpy="-1.570796326794896 0 0.7853981633974483"
		/>
		<xacro:roller_macro
			parent="${name}"
			name="n"
			xyz="0 0.04065 0.0165"
			rpy="-1.570796326794896 0 1.570796326794896"
		/>
		<xacro:roller_macro
			parent="${name}"
			name="nw"
			xyz="-0.02874389067 0.02874389067 -0.0165"
			rpy="-1.570796326794896 0 2.356194490192345"
		/>
		<xacro:roller_macro
			parent="${name}"
			name="w"
			xyz="-0.04065 0 0.0165"
			rpy="-1.570796326794896 0 3.141592653589793"
		/>
		<xacro:roller_macro
			parent="${name}"
			name="sw"
			xyz="-0.02874389067 -0.02874389067 -0.0165"
			rpy="-1.570796326794896 0 -2.356194490192345"
		/>
		<xacro:roller_macro
			parent="${name}"
			name="s"
			xyz="0 -0.04065 0.0165"
			rpy="-1.570796326794896 0 -1.570796326794896"
		/>
		<xacro:roller_macro
			parent="${name}"
			name="se"
			xyz="0.02874389067 -0.02874389067 -0.0165"
			rpy="-1.570796326794896 0 -0.7853981633974483"
		/>

		<transmission name="rim_${name}_transmission">
			<type>transmission_interface/SimpleTransmission</type>
			<joint name="rim_${name}_joint">
				<hardwareInterface>hardware_interface/VelocityJointInterface</hardwareInterface>
			</joint>
			<actuator name="rim_${name}_motor">
				<hardwareInterface>hardware_interface/VelocityJointInterface</hardwareInterface>
				<mechanicalReduction>1</mechanicalReduction>
			</actuator>
		</transmission>

	</xacro:macro>

</robot>
